Workbook
Name Slicer_Demand_Level: #N/A
Name Slicer_Weathersit: #N/A
Name Slicer_Weekday: #N/A

Sheet Combined_Data
A1: Instant | B1: Date | C1: Season | D1: Month | E1: Hr | F1: Holiday | G1: Weekday | H1: Weathersit | I1: Temp | J1: ATemp | K1: Hum | L1: WindsSpeed | M1: Casual | N1: Registered | O1: Cnt
A2: 1 | B2: 40544 | C2: Winter | D2: =TEXT(B2,"mmmm") -> January | E2: 0 | F2: FALSE | G2: =TEXT(B2,"dddd") -> Saturday | H2: Clear | I2: 0.24 | J2: 0.2879 | K2: 0.81 | L2: 0 | M2: 3 | N2: 13 | O2: 16
A3: 2 | B3: 40544 | C3: Winter | D3: =TEXT(B3,"mmmm") -> January | E3: 1 | F3: FALSE | G3: =TEXT(B3,"dddd") -> Saturday | H3: Clear | I3: 0.22 | J3: 0.2727 | K3: 0.8 | L3: 0 | M3: 8 | N3: 32 | O3: 40
A4: 3 | B4: 40544 | C4: Winter | D4: =TEXT(B4,"mmmm") -> January | E4: 2 | F4: FALSE | G4: =TEXT(B4,"dddd") -> Saturday | H4: Clear | I4: 0.22 | J4: 0.2727 | K4: 0.8 | L4: 0 | M4: 5 | N4: 27 | O4: 32
A5: 4 | B5: 40544 | C5: Winter | D5: =TEXT(B5,"mmmm") -> January | E5: 3 | F5: FALSE | G5: =TEXT(B5,"dddd") -> Saturday | H5: Clear | I5: 0.24 | J5: 0.2879 | K5: 0.75 | L5: 0 | M5: 3 | N5: 10 | O5: 13
A6: 5 | B6: 40544 | C6: Winter | D6: =TEXT(B6,"mmmm") -> January | E6: 4 | F6: FALSE | G6: =TEXT(B6,"dddd") -> Saturday | H6: Clear | I6: 0.24 | J6: 0.2879 | K6: 0.75 | L6: 0 | M6: 0 | N6: 1 | O6: 1
A7: 6 | B7: 40544 | C7: Winter | D7: =TEXT(B7,"mmmm") -> January | E7: 5 | F7: FALSE | G7: =TEXT(B7,"dddd") -> Saturday | H7: Mist | I7: 0.24 | J7: 0.2576 | K7: 0.75 | L7: 0.0896 | M7: 0 | N7: 1 | O7: 1
A8: 7 | B8: 40544 | C8: Winter | D8: =TEXT(B8,"mmmm") -> January | E8: 6 | F8: FALSE | G8: =TEXT(B8,"dddd") -> Saturday | H8: Clear | I8: 0.22 | J8: 0.2727 | K8: 0.8 | L8: 0 | M8: 2 | N8: 0 | O8: 2
A9: 8 | B9: 40544 | C9: Winter | D9: =TEXT(B9,"mmmm") -> January | E9: 7 | F9: FALSE | G9: =TEXT(B9,"dddd") -> Saturday | H9: Clear | I9: 0.2 | J9: 0.2576 | K9: 0.86 | L9: 0 | M9: 1 | N9: 2 | O9: 3
A10: 9 | B10: 40544 | C10: Winter | D10: =TEXT(B10,"mmmm") -> January | E10: 8 | F10: FALSE | G10: =TEXT(B10,"dddd") -> Saturday | H10: Clear | I10: 0.24 | J10: 0.197 | K10: 0.75 | L10: 0 | M10: 1 | N10: 7 | O10: 8
A11: 10 | B11: 40544 | C11: Winter | D11: =TEXT(B11,"mmmm") -> January | E11: 9 | F11: FALSE | G11: =TEXT(B11,"dddd") -> Saturday | H11: Clear | I11: 0.32 | J11: 0.3485 | K11: 0.76 | L11: 0 | M11: 8 | N11: 6 | O11: 14
A12: 11 | B12: 40544 | C12: Winter | D12: =TEXT(B12,"mmmm") -> January | E12: 10 | F12: FALSE | G12: =TEXT(B12,"dddd") -> Saturday | H12: Clear | I12: 0.38 | J12: 0.3939 | K12: 0.76 | L12: 0.2537 | M12: 12 | N12: 24 | O12: 36
A13: 12 | B13: 40544 | C13: Winter | D13: =TEXT(B13,"mmmm") -> January | E13: 11 | F13: FALSE | G13: =TEXT(B13,"dddd") -> Saturday | H13: Clear | I13: 0.36 | J13: 0.3333 | K13: 0.81 | L13: 0.2836 | M13: 26 | N13: 30 | O13: 56
... A611: 610 | B611: 40571 | C611: Winter | D611: =TEXT(B611,"mmmm") -> January | E611: 15 | F611: FALSE | G611: =TEXT(B611,"dddd") -> Friday | H611: Mist | I611: 0.2 | J611: 0.2576 | K611: 0.86 | L611: 0 | M611: 1 | N611: 40 | O611: 41

Sheet Derived_Data
A1: Instant | B1: Date | C1: Weekday | D1: Holiday | E1: Cnt | F1: Casual | G1: Registered | H1: Day_Type | I1: Day_Category | J1: Demand_Level | K1: Weathersit | L1: Weather_Score | T1: Weathersit | U1: Weather_Score
A2: 1 | B2: =INDEX('Combined_Data'!B:B, MATCH(Derived_Data!A2, 'Combined_Data'!A:A, 0)) -> 40544 | C2: =INDEX('Combined_Data'!G:G, MATCH(A2, 'Combined_Data'!A:A, 0)) -> Saturday | D2: =INDEX('Combined_Data'!F:F, MATCH(A2, 'Combined_Data'!A:A, 0)) -> FALSE | E2: =INDEX('Combined_Data'!O:O, MATCH(A2, 'Combined_Data'!A:A, 0)) -> 16 | F2: =INDEX('Combined_Data'!M:M, MATCH(A2, 'Combined_Data'!A:A, 0)) -> 3 | G2: =INDEX('Combined_Data'!N:N, MATCH(A2, 'Combined_Data'!A:A, 0)) -> 13 | H2: =IF(OR(TRIM(C2)="Saturday",TRIM(C2)="Sunday"),"Weekend","Weekday") -> Weekend | I2: =IF(D2=TRUE,"Holiday","Working Day") -> Working Day | J2: =IF(E2<100,"Low",IF(E2<=150,"Medium","High")) -> Low | K2: =INDEX('Combined_Data'!H:H, MATCH(A2, 'Combined_Data'!A:A, 0)) -> Clear | L2: =VLOOKUP(TRIM(K2), $T$2:$U$5, 2, FALSE) -> 1 | T2: Clear | U2: 1
A3: 2 | B3: =INDEX('Combined_Data'!B:B, MATCH(Derived_Data!A3, 'Combined_Data'!A:A, 0)) -> 40544 | C3: =INDEX('Combined_Data'!G:G, MATCH(A3, 'Combined_Data'!A:A, 0)) -> Saturday | D3: =INDEX('Combined_Data'!F:F, MATCH(A3, 'Combined_Data'!A:A, 0)) -> FALSE | E3: =INDEX('Combined_Data'!O:O, MATCH(A3, 'Combined_Data'!A:A, 0)) -> 40 | F3: =INDEX('Combined_Data'!M:M, MATCH(A3, 'Combined_Data'!A:A, 0)) -> 8 | G3: =INDEX('Combined_Data'!N:N, MATCH(A3, 'Combined_Data'!A:A, 0)) -> 32 | H3: =IF(OR(TRIM(C3)="Saturday",TRIM(C3)="Sunday"),"Weekend","Weekday") -> Weekend | I3: =IF(D3=TRUE,"Holiday","Working Day") -> Working Day | J3: =IF(E3<100,"Low",IF(E3<=150,"Medium","High")) -> Low | K3: =INDEX('Combined_Data'!H:H, MATCH(A3, 'Combined_Data'!A:A, 0)) -> Clear | L3: =VLOOKUP(TRIM(K3), $T$2:$U$5, 2, FALSE) -> 1 | T3: Mist | U3: 2
A4: 3 | B4: =INDEX('Combined_Data'!B:B, MATCH(Derived_Data!A4, 'Combined_Data'!A:A, 0)) -> 40544 | C4: =INDEX('Combined_Data'!G:G, MATCH(A4, 'Combined_Data'!A:A, 0)) -> Saturday | D4: =INDEX('Combined_Data'!F:F, MATCH(A4, 'Combined_Data'!A:A, 0)) -> FALSE | E4: =INDEX('Combined_Data'!O:O, MATCH(A4, 'Combined_Data'!A:A, 0)) -> 32 | F4: =INDEX('Combined_Data'!M:M, MATCH(A4, 'Combined_Data'!A:A, 0)) -> 5 | G4: =INDEX('Combined_Data'!N:N, MATCH(A4, 'Combined_Data'!A:A, 0)) -> 27 | H4: =IF(OR(TRIM(C4)="Saturday",TRIM(C4)="Sunday"),"Weekend","Weekday") -> Weekend | I4: =IF(D4=TRUE,"Holiday","Working Day") -> Working Day | J4: =IF(E4<100,"Low",IF(E4<=150,"Medium","High")) -> Low | K4: =INDEX('Combined_Data'!H:H, MATCH(A4, 'Combined_Data'!A:A, 0)) -> Clear | L4: =VLOOKUP(TRIM(K4), $T$2:$U$5, 2, FALSE) -> 1 | T4: Light Snow | U4: 3
A5: 4 | B5: =INDEX('Combined_Data'!B:B, MATCH(Derived_Data!A5, 'Combined_Data'!A:A, 0)) -> 40544 | C5: =INDEX('Combined_Data'!G:G, MATCH(A5, 'Combined_Data'!A:A, 0)) -> Saturday | D5: =INDEX('Combined_Data'!F:F, MATCH(A5, 'Combined_Data'!A:A, 0)) -> FALSE | E5: =INDEX('Combined_Data'!O:O, MATCH(A5, 'Combined_Data'!A:A, 0)) -> 13 | F5: =INDEX('Combined_Data'!M:M, MATCH(A5, 'Combined_Data'!A:A, 0)) -> 3 | G5: =INDEX('Combined_Data'!N:N, MATCH(A5, 'Combined_Data'!A:A, 0)) -> 10 | H5: =IF(OR(TRIM(C5)="Saturday",TRIM(C5)="Sunday"),"Weekend","Weekday") -> Weekend | I5: =IF(D5=TRUE,"Holiday","Working Day") -> Working Day | J5: =IF(E5<100,"Low",IF(E5<=150,"Medium","High")) -> Low | K5: =INDEX('Combined_Data'!H:H, MATCH(A5, 'Combined_Data'!A:A, 0)) -> Clear | L5: =VLOOKUP(TRIM(K5), $T$2:$U$5, 2, FALSE) -> 1 | T5: Heavy Snow | U5: 4
A6: 5 | B6: =INDEX('Combined_Data'!B:B, MATCH(Derived_Data!A6, 'Combined_Data'!A:A, 0)) -> 40544 | C6: =INDEX('Combined_Data'!G:G, MATCH(A6, 'Combined_Data'!A:A, 0)) -> Saturday | D6: =INDEX('Combined_Data'!F:F, MATCH(A6, 'Combined_Data'!A:A, 0)) -> FALSE | E6: =INDEX('Combined_Data'!O:O, MATCH(A6, 'Combined_Data'!A:A, 0)) -> 1 | F6: =INDEX('Combined_Data'!M:M, MATCH(A6, 'Combined_Data'!A:A, 0)) -> 0 | G6: =INDEX('Combined_Data'!N:N, MATCH(A6, 'Combined_Data'!A:A, 0)) -> 1 | H6: =IF(OR(TRIM(C6)="Saturday",TRIM(C6)="Sunday"),"Weekend","Weekday") -> Weekend | I6: =IF(D6=TRUE,"Holiday","Working Day") -> Working Day | J6: =IF(E6<100,"Low",IF(E6<=150,"Medium","High")) -> Low | K6: =INDEX('Combined_Data'!H:H, MATCH(A6, 'Combined_Data'!A:A, 0)) -> Clear | L6: =VLOOKUP(TRIM(K6), $T$2:$U$5, 2, FALSE) -> 1
A7: 6 | B7: =INDEX('Combined_Data'!B:B, MATCH(Derived_Data!A7, 'Combined_Data'!A:A, 0)) -> 40544 | C7: =INDEX('Combined_Data'!G:G, MATCH(A7, 'Combined_Data'!A:A, 0)) -> Saturday | D7: =INDEX('Combined_Data'!F:F, MATCH(A7, 'Combined_Data'!A:A, 0)) -> FALSE | E7: =INDEX('Combined_Data'!O:O, MATCH(A7, 'Combined_Data'!A:A, 0)) -> 1 | F7: =INDEX('Combined_Data'!M:M, MATCH(A7, 'Combined_Data'!A:A, 0)) -> 0 | G7: =INDEX('Combined_Data'!N:N, MATCH(A7, 'Combined_Data'!A:A, 0)) -> 1 | H7: =IF(OR(TRIM(C7)="Saturday",TRIM(C7)="Sunday"),"Weekend","Weekday") -> Weekend | I7: =IF(D7=TRUE,"Holiday","Working Day") -> Working Day | J7: =IF(E7<100,"Low",IF(E7<=150,"Medium","High")) -> Low | K7: =INDEX('Combined_Data'!H:H, MATCH(A7, 'Combined_Data'!A:A, 0)) -> Mist | L7: =VLOOKUP(TRIM(K7), $T$2:$U$5, 2, FALSE) -> 2
A8: 7 | B8: =INDEX('Combined_Data'!B:B, MATCH(Derived_Data!A8, 'Combined_Data'!A:A, 0)) -> 40544 | C8: =INDEX('Combined_Data'!G:G, MATCH(A8, 'Combined_Data'!A:A, 0)) -> Saturday | D8: =INDEX('Combined_Data'!F:F, MATCH(A8, 'Combined_Data'!A:A, 0)) -> FALSE | E8: =INDEX('Combined_Data'!O:O, MATCH(A8, 'Combined_Data'!A:A, 0)) -> 2 | F8: =INDEX('Combined_Data'!M:M, MATCH(A8, 'Combined_Data'!A:A, 0)) -> 2 | G8: =INDEX('Combined_Data'!N:N, MATCH(A8, 'Combined_Data'!A:A, 0)) -> 0 | H8: =IF(OR(TRIM(C8)="Saturday",TRIM(C8)="Sunday"),"Weekend","Weekday") -> Weekend | I8: =IF(D8=TRUE,"Holiday","Working Day") -> Working Day | J8: =IF(E8<100,"Low",IF(E8<=150,"Medium","High")) -> Low | K8: =INDEX('Combined_Data'!H:H, MATCH(A8, 'Combined_Data'!A:A, 0)) -> Clear | L8: =VLOOKUP(TRIM(K8), $T$2:$U$5, 2, FALSE) -> 1
A9: 8 | B9: =INDEX('Combined_Data'!B:B, MATCH(Derived_Data!A9, 'Combined_Data'!A:A, 0)) -> 40544 | C9: =INDEX('Combined_Data'!G:G, MATCH(A9, 'Combined_Data'!A:A, 0)) -> Saturday | D9: =INDEX('Combined_Data'!F:F, MATCH(A9, 'Combined_Data'!A:A, 0)) -> FALSE | E9: =INDEX('Combined_Data'!O:O, MATCH(A9, 'Combined_Data'!A:A, 0)) -> 3 | F9: =INDEX('Combined_Data'!M:M, MATCH(A9, 'Combined_Data'!A:A, 0)) -> 1 | G9: =INDEX('Combined_Data'!N:N, MATCH(A9, 'Combined_Data'!A:A, 0)) -> 2 | H9: =IF(OR(TRIM(C9)="Saturday",TRIM(C9)="Sunday"),"Weekend","Weekday") -> Weekend | I9: =IF(D9=TRUE,"Holiday","Working Day") -> Working Day | J9: =IF(E9<100,"Low",IF(E9<=150,"Medium","High")) -> Low | K9: =INDEX('Combined_Data'!H:H, MATCH(A9, 'Combined_Data'!A:A, 0)) -> Clear | L9: =VLOOKUP(TRIM(K9), $T$2:$U$5, 2, FALSE) -> 1
A10: 9 | B10: =INDEX('Combined_Data'!B:B, MATCH(Derived_Data!A10, 'Combined_Data'!A:A, 0)) -> 40544 | C10: =INDEX('Combined_Data'!G:G, MATCH(A10, 'Combined_Data'!A:A, 0)) -> Saturday | D10: =INDEX('Combined_Data'!F:F, MATCH(A10, 'Combined_Data'!A:A, 0)) -> FALSE | E10: =INDEX('Combined_Data'!O:O, MATCH(A10, 'Combined_Data'!A:A, 0)) -> 8 | F10: =INDEX('Combined_Data'!M:M, MATCH(A10, 'Combined_Data'!A:A, 0)) -> 1 | G10: =INDEX('Combined_Data'!N:N, MATCH(A10, 'Combined_Data'!A:A, 0)) -> 7 | H10: =IF(OR(TRIM(C10)="Saturday",TRIM(C10)="Sunday"),"Weekend","Weekday") -> Weekend | I10: =IF(D10=TRUE,"Holiday","Working Day") -> Working Day | J10: =IF(E10<100,"Low",IF(E10<=150,"Medium","High")) -> Low | K10: =INDEX('Combined_Data'!H:H, MATCH(A10, 'Combined_Data'!A:A, 0)) -> Clear | L10: =VLOOKUP(TRIM(K10), $T$2:$U$5, 2, FALSE) -> 1
A11: 10 | B11: =INDEX('Combined_Data'!B:B, MATCH(Derived_Data!A11, 'Combined_Data'!A:A, 0)) -> 40544 | C11: =INDEX('Combined_Data'!G:G, MATCH(A11, 'Combined_Data'!A:A, 0)) -> Saturday | D11: =INDEX('Combined_Data'!F:F, MATCH(A11, 'Combined_Data'!A:A, 0)) -> FALSE | E11: =INDEX('Combined_Data'!O:O, MATCH(A11, 'Combined_Data'!A:A, 0)) -> 14 | F11: =INDEX('Combined_Data'!M:M, MATCH(A11, 'Combined_Data'!A:A, 0)) -> 8 | G11: =INDEX('Combined_Data'!N:N, MATCH(A11, 'Combined_Data'!A:A, 0)) -> 6 | H11: =IF(OR(TRIM(C11)="Saturday",TRIM(C11)="Sunday"),"Weekend","Weekday") -> Weekend | I11: =IF(D11=TRUE,"Holiday","Working Day") -> Working Day | J11: =IF(E11<100,"Low",IF(E11<=150,"Medium","High")) -> Low | K11: =INDEX('Combined_Data'!H:H, MATCH(A11, 'Combined_Data'!A:A, 0)) -> Clear | L11: =VLOOKUP(TRIM(K11), $T$2:$U$5, 2, FALSE) -> 1
A12: 11 | B12: =INDEX('Combined_Data'!B:B, MATCH(Derived_Data!A12, 'Combined_Data'!A:A, 0)) -> 40544 | C12: =INDEX('Combined_Data'!G:G, MATCH(A12, 'Combined_Data'!A:A, 0)) -> Saturday | D12: =INDEX('Combined_Data'!F:F, MATCH(A12, 'Combined_Data'!A:A, 0)) -> FALSE | E12: =INDEX('Combined_Data'!O:O, MATCH(A12, 'Combined_Data'!A:A, 0)) -> 36 | F12: =INDEX('Combined_Data'!M:M, MATCH(A12, 'Combined_Data'!A:A, 0)) -> 12 | G12: =INDEX('Combined_Data'!N:N, MATCH(A12, 'Combined_Data'!A:A, 0)) -> 24 | H12: =IF(OR(TRIM(C12)="Saturday",TRIM(C12)="Sunday"),"Weekend","Weekday") -> Weekend | I12: =IF(D12=TRUE,"Holiday","Working Day") -> Working Day | J12: =IF(E12<100,"Low",IF(E12<=150,"Medium","High")) -> Low | K12: =INDEX('Combined_Data'!H:H, MATCH(A12, 'Combined_Data'!A:A, 0)) -> Clear | L12: =VLOOKUP(TRIM(K12), $T$2:$U$5, 2, FALSE) -> 1
A13: 12 | B13: =INDEX('Combined_Data'!B:B, MATCH(Derived_Data!A13, 'Combined_Data'!A:A, 0)) -> 40544 | C13: =INDEX('Combined_Data'!G:G, MATCH(A13, 'Combined_Data'!A:A, 0)) -> Saturday | D13: =INDEX('Combined_Data'!F:F, MATCH(A13, 'Combined_Data'!A:A, 0)) -> FALSE | E13: =INDEX('Combined_Data'!O:O, MATCH(A13, 'Combined_Data'!A:A, 0)) -> 56 | F13: =INDEX('Combined_Data'!M:M, MATCH(A13, 'Combined_Data'!A:A, 0)) -> 26 | G13: =INDEX('Combined_Data'!N:N, MATCH(A13, 'Combined_Data'!A:A, 0)) -> 30 | H13: =IF(OR(TRIM(C13)="Saturday",TRIM(C13)="Sunday"),"Weekend","Weekday") -> Weekend | I13: =IF(D13=TRUE,"Holiday","Working Day") -> Working Day | J13: =IF(E13<100,"Low",IF(E13<=150,"Medium","High")) -> Low | K13: =INDEX('Combined_Data'!H:H, MATCH(A13, 'Combined_Data'!A:A, 0)) -> Clear | L13: =VLOOKUP(TRIM(K13), $T$2:$U$5, 2, FALSE) -> 1
A14: 13 | B14: =INDEX('Combined_Data'!B:B, MATCH(Derived_Data!A14, 'Combined_Data'!A:A, 0)) -> 40544 | C14: =INDEX('Combined_Data'!G:G, MATCH(A14, 'Combined_Data'!A:A, 0)) -> Saturday | D14: =INDEX('Combined_Data'!F:F, MATCH(A14, 'Combined_Data'!A:A, 0)) -> FALSE | E14: =INDEX('Combined_Data'!O:O, MATCH(A14, 'Combined_Data'!A:A, 0)) -> 84 | F14: =INDEX('Combined_Data'!M:M, MATCH(A14, 'Combined_Data'!A:A, 0)) -> 29 | G14: =INDEX('Combined_Data'!N:N, MATCH(A14, 'Combined_Data'!A:A, 0)) -> 55 | H14: =IF(OR(TRIM(C14)="Saturday",TRIM(C14)="Sunday"),"Weekend","Weekday") -> Weekend | I14: =IF(D14=TRUE,"Holiday","Working Day") -> Working Day | J14: =IF(E14<100,"Low",IF(E14<=150,"Medium","High")) -> Low | K14: =INDEX('Combined_Data'!H:H, MATCH(A14, 'Combined_Data'!A:A, 0)) -> Clear | L14: =VLOOKUP(TRIM(K14), $T$2:$U$5, 2, FALSE) -> 1
A15: 14 | B15: =INDEX('Combined_Data'!B:B, MATCH(Derived_Data!A15, 'Combined_Data'!A:A, 0)) -> 40544 | C15: =INDEX('Combined_Data'!G:G, MATCH(A15, 'Combined_Data'!A:A, 0)) -> Saturday | D15: =INDEX('Combined_Data'!F:F, MATCH(A15, 'Combined_Data'!A:A, 0)) -> FALSE | E15: =INDEX('Combined_Data'!O:O, MATCH(A15, 'Combined_Data'!A:A, 0)) -> 94 | F15: =INDEX('Combined_Data'!M:M, MATCH(A15, 'Combined_Data'!A:A, 0)) -> 47 | G15: =INDEX('Combined_Data'!N:N, MATCH(A15, 'Combined_Data'!A:A, 0)) -> 47 | H15: =IF(OR(TRIM(C15)="Saturday",TRIM(C15)="Sunday"),"Weekend","Weekday") -> Weekend | I15: =IF(D15=TRUE,"Holiday","Working Day") -> Working Day | J15: =IF(E15<100,"Low",IF(E15<=150,"Medium","High")) -> Low | K15: =INDEX('Combined_Data'!H:H, MATCH(A15, 'Combined_Data'!A:A, 0)) -> Mist | L15: =VLOOKUP(TRIM(K15), $T$2:$U$5, 2, FALSE) -> 2
A16: 15 | B16: =INDEX('Combined_Data'!B:B, MATCH(Derived_Data!A16, 'Combined_Data'!A:A, 0)) -> 40544 | C16: =INDEX('Combined_Data'!G:G, MATCH(A16, 'Combined_Data'!A:A, 0)) -> Saturday | D16: =INDEX('Combined_Data'!F:F, MATCH(A16, 'Combined_Data'!A:A, 0)) -> FALSE | E16: =INDEX('Combined_Data'!O:O, MATCH(A16, 'Combined_Data'!A:A, 0)) -> 106 | F16: =INDEX('Combined_Data'!M:M, MATCH(A16, 'Combined_Data'!A:A, 0)) -> 35 | G16: =INDEX('Combined_Data'!N:N, MATCH(A16, 'Combined_Data'!A:A, 0)) -> 71 | H16: =IF(OR(TRIM(C16)="Saturday",TRIM(C16)="Sunday"),"Weekend","Weekday") -> Weekend | I16: =IF(D16=TRUE,"Holiday","Working Day") -> Working Day | J16: =IF(E16<100,"Low",IF(E16<=150,"Medium","High")) -> Medium | K16: =INDEX('Combined_Data'!H:H, MATCH(A16, 'Combined_Data'!A:A, 0)) -> Mist | L16: =VLOOKUP(TRIM(K16), $T$2:$U$5, 2, FALSE) -> 2
A17: 16 | B17: =INDEX('Combined_Data'!B:B, MATCH(Derived_Data!A17, 'Combined_Data'!A:A, 0)) -> 40544 | C17: =INDEX('Combined_Data'!G:G, MATCH(A17, 'Combined_Data'!A:A, 0)) -> Saturday | D17: =INDEX('Combined_Data'!F:F, MATCH(A17, 'Combined_Data'!A:A, 0)) -> FALSE | E17: =INDEX('Combined_Data'!O:O, MATCH(A17, 'Combined_Data'!A:A, 0)) -> 110 | F17: =INDEX('Combined_Data'!M:M, MATCH(A17, 'Combined_Data'!A:A, 0)) -> 40 | G17: =INDEX('Combined_Data'!N:N, MATCH(A17, 'Combined_Data'!A:A, 0)) -> 70 | H17: =IF(OR(TRIM(C17)="Saturday",TRIM(C17)="Sunday"),"Weekend","Weekday") -> Weekend | I17: =IF(D17=TRUE,"Holiday","Working Day") -> Working Day | J17: =IF(E17<100,"Low",IF(E17<=150,"Medium","High")) -> Medium | K17: =INDEX('Combined_Data'!H:H, MATCH(A17, 'Combined_Data'!A:A, 0)) -> Mist | L17: =VLOOKUP(TRIM(K17), $T$2:$U$5, 2, FALSE) -> 2
... A611: 610 | B611: =INDEX('Combined_Data'!B:B, MATCH(Derived_Data!A611, 'Combined_Data'!A:A, 0)) -> 40571 | C611: =INDEX('Combined_Data'!G:G, MATCH(A611, 'Combined_Data'!A:A, 0)) -> Friday | D611: =INDEX('Combined_Data'!F:F, MATCH(A611, 'Combined_Data'!A:A, 0)) -> FALSE | E611: =INDEX('Combined_Data'!O:O, MATCH(A611, 'Combined_Data'!A:A, 0)) -> 41 | F611: =INDEX('Combined_Data'!M:M, MATCH(A611, 'Combined_Data'!A:A, 0)) -> 1 | G611: =INDEX('Combined_Data'!N:N, MATCH(A611, 'Combined_Data'!A:A, 0)) -> 40 | H611: =IF(OR(TRIM(C611)="Saturday",TRIM(C611)="Sunday"),"Weekend","Weekday") -> Weekday | I611: =IF(D611=TRUE,"Holiday","Working Day") -> Working Day | J611: =IF(E611<100,"Low",IF(E611<=150,"Medium","High")) -> Low | K611: =INDEX('Combined_Data'!H:H, MATCH(A611, 'Combined_Data'!A:A, 0)) -> Mist | L611: =VLOOKUP(TRIM(K611), $T$2:$U$5, 2, FALSE) -> 2

Sheet Pivot_Table
A1: Average Daily Temperature | D1: Daily Counts by Weather Condition | I1: Sum of Temperature by Weather Condition | L1: Temperature by Weather
A3: Row Labels | B3: Average of Temp | D3: Row Labels | E3: Average of Cnt | F3: Average of Casual | G3: Average of Registered | I3: Row Labels | J3: Sum of Temp | L3: Row Labels | M3: Count of ATemp
A4: Monday | B4: 0.15483871 | D4: Clear | E4: 59.709239 | F4: 4.4646739 | G4: 55.244565 | I4: Clear | J4: 66.48 | L4: Clear | M4: 368
A5: Tuesday | B5: 0.20075 | D5: Heavy Snow | E5: 36 | F5: 1 | G5: 35 | I5: Heavy Snow | J5: 0.22 | L5: Heavy Snow | M5: 1
A6: Wednesday | B6: 0.22880952 | D6: Light Snow | E6: 31.12766 | F6: 2.1489362 | G6: 28.978723 | I6: Light Snow | J6: 10.4 | L6: Light Snow | M6: 47
A7: Thursday | B7: 0.20886076 | D7: Mist | E7: 53.742268 | F7: 5.1597938 | G7: 48.582474 | I7: Mist | J7: 43 | L7: Mist | M7: 194
A8: Friday | B8: 0.17976471 | D8: Grand Total | E8: 55.570492 | F8: 4.5016393 | G8: 51.068852 | I8: Grand Total | J8: 120.1 | L8: Grand Total | M8: 610
A9: Saturday | B9: 0.20189474
A10: Sunday | B10: 0.20702128 | D10: Count by Demand | G10: Total Count on Day Type
A11: Grand Total | B11: 0.19688525 | J11: Average of Cnt | L11: Total Count by Dates
D12: Demand Level | E12: Count of Cnt | G12: Weekend v/s Weekdays | H12: Sum of Cnt | I12: Count of Demand_Level | J12: 55.570492 | K12: Total Bike Rentals
D13: High | E13: 39 | G13: Weekday | H13: 25912 | I13: 610 | K13: 33898 | L13: Row Labels | M13: Sum of Cnt
A14: Average Hour Count | D14: Low | E14: 520 | G14: Weekend | H14: 7986 | J14: Peak Demand | L14: 40544 | M14: 985
D15: Medium | E15: 51 | G15: Grand Total | H15: 33898 | J15: 249 | L15: 40545 | M15: 801
A16: Row Labels | B16: Average of Cnt | D16: Grand Total | E16: 610 | L16: 40546 | M16: 1349
A17: 0 | B17: 14.230769 | I17: Peak Demand on Weathersit | L17: 40547 | M17: 1562
A18: 1 | B18: 9.1923077 | D18: Data According to Weekdays | L18: 40548 | M18: 1600
A19: 2 | B19: 7.0833333 | I19: Temp on peak demands | J19: Count of Weathersit | L19: 40549 | M19: 1606
A20: 3 | B20: 4.75 | D20: Row Labels | E20: Average of WindsSpeed | F20: Average of ATemp | G20: Average of Temp | I20: High | J20: 39 | L20: 40550 | M20: 1510
A21: 4 | B21: 1.9 | D21: Monday | E21: 0.2055828 | F21: 0.15836559 | G21: 0.15483871 | I21: Low | J21: 520 | L21: 40551 | M21: 959
A22: 5 | B22: 3.9583333 | D22: Tuesday | E22: 0.13900375 | F22: 0.21610375 | G22: 0.20075 | I22: Medium | J22: 51 | L22: 40552 | M22: 822
A23: 6 | B23: 18.307692 | D23: Wednesday | E23: 0.24396905 | F23: 0.22529643 | G23: 0.22880952 | I23: Grand Total | J23: 610 | L23: 40553 | M23: 1321
A24: 7 | B24: 53.576923 | D24: Thursday | E24: 0.18856203 | F24: 0.21346582 | G24: 0.20886076 | L24: 40554 | M24: 1263
A25: 8 | B25: 127.61538 | D25: Friday | E25: 0.19684706 | F25: 0.19038 | G25: 0.17976471 | L25: 40555 | M25: 1162
A26: 9 | B26: 84.461538 | D26: Saturday | E26: 0.18947789 | F26: 0.20845895 | G26: 0.20189474 | I26: Total Count Weather Demand | L26: 40556 | M26: 1406
A27: 10 | B27: 50.038462 | D27: Sunday | E27: 0.26167447 | F27: 0.19294787 | G27: 0.20702128 | L27: 40557 | M27: 1421
A28: 11 | B28: 55.961538 | D28: Grand Total | E28: 0.20485098 | F28: 0.19988197 | G28: 0.19688525 | I28: Row Labels | J28: Count of Cnt | L28: 40558 | M28: 1248
A29: 12 | B29: 71.703704 | I29: High | J29: 39 | L29: 40559 | M29: 1204
A30: 13 | B30: 74.62963 | I30: Low | J30: 520 | L30: 40560 | M30: 1000
A31: 14 | B31: 67.666667 | I31: Medium | J31: 51 | L31: 40561 | M31: 683
A32: 15 | B32: 71.62963 | I32: Grand Total | J32: 610 | L32: 40562 | M32: 1650
A33: 16 | B33: 81.481481 | L33: 40563 | M33: 1927
A34: 17 | B34: 131.48148 | E34: Average of Temperature & COUNT on Weekdays | L34: 40564 | M34: 1543
A35: 18 | B35: 118.53846 | L35: 40565 | M35: 981
A36: 19 | B36: 85.115385 | E36: Row Labels | F36: Average of Temp | G36: Average of Cnt | L36: 40566 | M36: 986
A37: 20 | B37: 59.269231 | E37: Monday | F37: 0.15483871 | G37: 54.688172 | L37: 40567 | M37: 1416
A38: 21 | B38: 41.346154 | E38: Tuesday | F38: 0.20075 | G38: 68.6625 | I38: Maximum Count on Day Type | L38: 40568 | M38: 1985
A39: 22 | B39: 32.230769 | E39: Wednesday | F39: 0.22880952 | G39: 58.547619 | L39: 40569 | M39: 506
A40: 23 | B40: 21.538462 | E40: Thursday | F40: 0.20886076 | G40: 67.974684 | I40: Row Labels | J40: Max of Cnt | L40: 40570 | M40: 431
A41: (blank) | E41: Friday | F41: 0.17976471 | G41: 59.352941 | I41: Weekday | J41: 249 | L41: 40571 | M41: 571
...

Sheet DashBoard
O12: \
